Exception on / [GET]
Traceback (most recent call last):
  File "/usr/local/lib/python2.7/site-packages/Flask-0.11.1-py2.7.egg/flask/app.py", line 1988, in wsgi_app
    response = self.full_dispatch_request()
  File "/usr/local/lib/python2.7/site-packages/Flask-0.11.1-py2.7.egg/flask/app.py", line 1641, in full_dispatch_request
    rv = self.handle_user_exception(e)
  File "/usr/local/lib/python2.7/site-packages/Flask-0.11.1-py2.7.egg/flask/app.py", line 1544, in handle_user_exception
    reraise(exc_type, exc_value, tb)
  File "/usr/local/lib/python2.7/site-packages/Flask-0.11.1-py2.7.egg/flask/app.py", line 1639, in full_dispatch_request
    rv = self.dispatch_request()
  File "/usr/local/lib/python2.7/site-packages/Flask-0.11.1-py2.7.egg/flask/app.py", line 1625, in dispatch_request
    return self.view_functions[rule.endpoint](**req.view_args)
  File "index.py", line 16, in index
    return 1 / 0
ZeroDivisionError: integer division or modulo by zero
Exception on / [GET]
Traceback (most recent call last):
  File "/usr/local/lib/python2.7/site-packages/Flask-0.11.1-py2.7.egg/flask/app.py", line 1988, in wsgi_app
    response = self.full_dispatch_request()
  File "/usr/local/lib/python2.7/site-packages/Flask-0.11.1-py2.7.egg/flask/app.py", line 1642, in full_dispatch_request
    response = self.make_response(rv)
  File "/usr/local/lib/python2.7/site-packages/Flask-0.11.1-py2.7.egg/flask/app.py", line 1746, in make_response
    rv = self.response_class.force_type(rv, request.environ)
  File "/usr/local/lib/python2.7/site-packages/Werkzeug-0.11.11-py2.7.egg/werkzeug/wrappers.py", line 847, in force_type
    response = BaseResponse(*_run_wsgi_app(response, environ))
  File "/usr/local/lib/python2.7/site-packages/Werkzeug-0.11.11-py2.7.egg/werkzeug/wrappers.py", line 57, in _run_wsgi_app
    return _run_wsgi_app(*args)
  File "/usr/local/lib/python2.7/site-packages/Werkzeug-0.11.11-py2.7.egg/werkzeug/test.py", line 871, in run_wsgi_app
    app_rv = app(environ, start_response)
TypeError: 'int' object is not callable
Exception on / [GET]
Traceback (most recent call last):
  File "/usr/local/lib/python2.7/site-packages/Flask-0.11.1-py2.7.egg/flask/app.py", line 1988, in wsgi_app
    response = self.full_dispatch_request()
  File "/usr/local/lib/python2.7/site-packages/Flask-0.11.1-py2.7.egg/flask/app.py", line 1642, in full_dispatch_request
    response = self.make_response(rv)
  File "/usr/local/lib/python2.7/site-packages/Flask-0.11.1-py2.7.egg/flask/app.py", line 1746, in make_response
    rv = self.response_class.force_type(rv, request.environ)
  File "/usr/local/lib/python2.7/site-packages/Werkzeug-0.11.11-py2.7.egg/werkzeug/wrappers.py", line 847, in force_type
    response = BaseResponse(*_run_wsgi_app(response, environ))
  File "/usr/local/lib/python2.7/site-packages/Werkzeug-0.11.11-py2.7.egg/werkzeug/wrappers.py", line 57, in _run_wsgi_app
    return _run_wsgi_app(*args)
  File "/usr/local/lib/python2.7/site-packages/Werkzeug-0.11.11-py2.7.egg/werkzeug/test.py", line 871, in run_wsgi_app
    app_rv = app(environ, start_response)
TypeError: 'int' object is not callable
Exception on / [GET]
Traceback (most recent call last):
  File "/usr/local/lib/python2.7/site-packages/Flask-0.11.1-py2.7.egg/flask/app.py", line 1988, in wsgi_app
    response = self.full_dispatch_request()
  File "/usr/local/lib/python2.7/site-packages/Flask-0.11.1-py2.7.egg/flask/app.py", line 1642, in full_dispatch_request
    response = self.make_response(rv)
  File "/usr/local/lib/python2.7/site-packages/Flask-0.11.1-py2.7.egg/flask/app.py", line 1746, in make_response
    rv = self.response_class.force_type(rv, request.environ)
  File "/usr/local/lib/python2.7/site-packages/Werkzeug-0.11.11-py2.7.egg/werkzeug/wrappers.py", line 847, in force_type
    response = BaseResponse(*_run_wsgi_app(response, environ))
  File "/usr/local/lib/python2.7/site-packages/Werkzeug-0.11.11-py2.7.egg/werkzeug/wrappers.py", line 57, in _run_wsgi_app
    return _run_wsgi_app(*args)
  File "/usr/local/lib/python2.7/site-packages/Werkzeug-0.11.11-py2.7.egg/werkzeug/test.py", line 871, in run_wsgi_app
    app_rv = app(environ, start_response)
TypeError: 'int' object is not callable
